Workbook

Sheet Assumptions
A1: Closed-Loop Nitrogen Spray Drying — Hour-by-Hour Condensation Analysis
A2: No saturation assumption: humidity, vapour pressure, and dew point are recalculated every hour from the actual recirculating vapour load
A4: SYSTEM INPUTS (Given Data)
A5: Parameter | B5: Value | C5: Unit | D5: Notes
A6: Nitrogen circulation rate | B6: 3000 | C6: kg/hr | D6: Dry N2 basis (carrier gas mass flow), constant in closed loop
A7: Fresh water evaporation rate | B7: 50 | C7: kg/hr | D7: New water vapour added to the loop each hour, from the dryer
A8: Total system pressure | B8: 1 | C8: atm | D8: Held constant; 1 atm = 760 mmHg
A9: MW of water | B9: 18.015 | C9: g/mol | D9: Used in mole-to-mass conversion for humidity ratio
A10: MW of nitrogen | B10: 28.014 | C10: g/mol | D10: Used in mole-to-mass conversion for humidity ratio
A11: Chiller per-pass condensation efficiency (eta) | B11: 0.75 | C11: fraction | D11: Fraction of the excess-above-saturation vapour removed each hour by a real, non-ideal chiller
A12: Simulation horizon | B12: 12 | C12: hours | D12: Hours simulated per outlet temperature; system reaches steady state by ~hour 9
A14: WHY NO SATURATION ASSUMPTION IS MADE
A15: The gas circulating in the loop is never assumed to be saturated at the chiller outlet temperature. Instead, every hour: (1) the actual water vapour mass entering the chiller is known exactly (previous hour's carryover + 50 kg/hr fresh evaporation); (2) this gives an ACTUAL humidity ratio and, via Dalton's Law, an ACTUAL water partial pressure; (3) inverting the Antoine equation on that actual partial pressure gives the REAL dew point of the gas entering the chiller THAT HOUR — this value changes hour to hour as vapour recirculates and builds up. Separately, the chiller's saturation CAPACITY at its fixed outlet temperature is calculated once (this is a property of the outlet temperature only, via Raoult's Law at the condensing surface: the condensate is pure water, x=1, so the equilibrium vapour pressure ceiling is exactly Psat(T)). The chiller removes a fraction (eta) of whatever vapour sits above that capacity each hour; the rest recirculates and adds to next hour's incoming load.
A17: GOVERNING EQUATIONS (applied fresh, every hour)
A18: 1. Vapour entering chiller this hour: W(in) = Carryover(previous hour) + 50 kg/hr
A19: 2. Actual humidity ratio: Y = W(in) / N2 flow [kg H2O / kg N2]
A20: 3. Mole ratio: k = Y x (MW_N2 / MW_H2O)
A21: 4. Dalton's Law (rearranged): p(H2O), actual = k x P_total / (1+k)
A22: 5. Antoine equation inverted -> actual dew point this hour: T(dew) = 1730.63/(8.07131-log10[p(H2O)]) - 233.426
A23: 6. Raoult's Law at the condensing surface (pure water condensate, x=1): p(H2O), equilibrium = Psat(T_outlet) -- this sets the saturation CAPACITY ceiling at the fixed chiller outlet T
A24: 7. Saturation capacity at outlet T: Y_sat(T) = (Psat(T)/p(N2)(T)) x (MW_H2O/MW_N2); Cap = Y_sat(T) x N2 flow
A25: 8. Excess above capacity: Excess = max[W(in) - Cap, 0]
A26: 9. Water condensed this hour: W(cond) = eta x Excess
A27: 10. Carryover to next hour: Carryover = W(in) - W(cond)

Sheet Hour-by-Hour Balance
A1: Hour-by-Hour Mass Balance — Humidity, Dew Point, and Condensation Recalculated Every Hour
A2: No saturation assumption. Each row uses the previous row's carryover as part of this hour's incoming vapour load.
A4: eta (chiller efficiency, per-pass) | B4: =Assumptions!$B$11 -> 0.75
A6: OUTLET TEMPERATURE = 10 C | E6: Psat(T), mmHg = | F6: =IF(10>=0,10^(8.07131-1730.63/(233.426+10)),6.1115*EXP(22.452*10/(272.55+10))*0.750062) -> 9.1588165 | G6: Cap(T), kg/hr = | H6: =(($F$6)/(760-$F$6))*(Assumptions!$B$9/Assumptions!$B$10)*Assumptions!$B$6 -> 23.532695
A7: Hour | B7: Vapour Entering, W(in) (kg) | C7: Humidity Ratio, Y (kg/kg) | D7: p(H2O), actual (mmHg) | E7: Dew Point This Hour (C) | F7: Excess Above Capacity (kg) | G7: Condensed This Hour (kg/hr) | H7: Carryover After (kg) | I7: % of Evap. Condensed
A8: 1 | B8: =Assumptions!$B$7 -> 50 | C8: =B8/Assumptions!$B$6 -> 0.016666667 | D8: =(C8*(Assumptions!$B$10/Assumptions!$B$9))*760/(1+(C8*(Assumptions!$B$10/Assumptions!$B$9))) -> 19.199541 | E8: =1730.63/(8.07131-LOG10(D8))-233.426 -> 21.527612 | F8: =MAX(B8-$H$6,0) -> 26.467305 | G8: =$B$4*F8 -> 19.850479 | H8: =B8-G8 -> 30.149521 | I8: =G8/Assumptions!$B$7 -> 0.39700957
A9: 2 | B9: =H8+Assumptions!$B$7 -> 80.149521 | C9: =B9/Assumptions!$B$6 -> 0.026716507 | D9: =(C9*(Assumptions!$B$10/Assumptions!$B$9))*760/(1+(C9*(Assumptions!$B$10/Assumptions!$B$9))) -> 30.314892 | E9: =1730.63/(8.07131-LOG10(D9))-233.426 -> 29.202357 | F9: =MAX(B9-$H$6,0) -> 56.616826 | G9: =$B$4*F9 -> 42.46262 | H9: =B9-G9 -> 37.686902 | I9: =G9/Assumptions!$B$7 -> 0.84925239
A10: 3 | B10: =H9+Assumptions!$B$7 -> 87.686902 | C10: =B10/Assumptions!$B$6 -> 0.029228967 | D10: =(C10*(Assumptions!$B$10/Assumptions!$B$9))*760/(1+(C10*(Assumptions!$B$10/Assumptions!$B$9))) -> 33.041805 | E10: =1730.63/(8.07131-LOG10(D10))-233.426 -> 30.701742 | F10: =MAX(B10-$H$6,0) -> 64.154207 | G10: =$B$4*F10 -> 48.115655 | H10: =B10-G10 -> 39.571247 | I10: =G10/Assumptions!$B$7 -> 0.9623131
A11: 4 | B11: =H10+Assumptions!$B$7 -> 89.571247 | C11: =B11/Assumptions!$B$6 -> 0.029857082 | D11: =(C11*(Assumptions!$B$10/Assumptions!$B$9))*760/(1+(C11*(Assumptions!$B$10/Assumptions!$B$9))) -> 33.720352 | E11: =1730.63/(8.07131-LOG10(D11))-233.426 -> 31.058101 | F11: =MAX(B11-$H$6,0) -> 66.038552 | G11: =$B$4*F11 -> 49.528914 | H11: =B11-G11 -> 40.042333 | I11: =G11/Assumptions!$B$7 -> 0.99057827
A12: 5 | B12: =H11+Assumptions!$B$7 -> 90.042333 | C12: =B12/Assumptions!$B$6 -> 0.030014111 | D12: =(C12*(Assumptions!$B$10/Assumptions!$B$9))*760/(1+(C12*(Assumptions!$B$10/Assumptions!$B$9))) -> 33.889791 | E12: =1730.63/(8.07131-LOG10(D12))-233.426 -> 31.146116 | F12: =MAX(B12-$H$6,0) -> 66.509638 | G12: =$B$4*F12 -> 49.882228 | H12: =B12-G12 -> 40.160105 | I12: =G12/Assumptions!$B$7 -> 0.99764457
A13: 6 | B13: =H12+Assumptions!$B$7 -> 90.160105 | C13: =B13/Assumptions!$B$6 -> 0.030053368 | D13: =(C13*(Assumptions!$B$10/Assumptions!$B$9))*760/(1+(C13*(Assumptions!$B$10/Assumptions!$B$9))) -> 33.932138 | E13: =1730.63/(8.07131-LOG10(D13))-233.426 -> 31.168053 | F13: =MAX(B13-$H$6,0) -> 66.627409 | G13: =$B$4*F13 -> 49.970557 | H13: =B13-G13 -> 40.189548 | I13: =G13/Assumptions!$B$7 -> 0.99941114
A14: 7 | B14: =H13+Assumptions!$B$7 -> 90.189548 | C14: =B14/Assumptions!$B$6 -> 0.030063183 | D14: =(C14*(Assumptions!$B$10/Assumptions!$B$9))*760/(1+(C14*(Assumptions!$B$10/Assumptions!$B$9))) -> 33.942724 | E14: =1730.63/(8.07131-LOG10(D14))-233.426 -> 31.173534 | F14: =MAX(B14-$H$6,0) -> 66.656852 | G14: =$B$4*F14 -> 49.992639 | H14: =B14-G14 -> 40.196908 | I14: =G14/Assumptions!$B$7 -> 0.99985279
A15: 8 | B15: =H14+Assumptions!$B$7 -> 90.196908 | C15: =B15/Assumptions!$B$6 -> 0.030065636 | D15: =(C15*(Assumptions!$B$10/Assumptions!$B$9))*760/(1+(C15*(Assumptions!$B$10/Assumptions!$B$9))) -> 33.945371 | E15: =1730.63/(8.07131-LOG10(D15))-233.426 -> 31.174903 | F15: =MAX(B15-$H$6,0) -> 66.664213 | G15: =$B$4*F15 -> 49.99816 | H15: =B15-G15 -> 40.198749 | I15: =G15/Assumptions!$B$7 -> 0.9999632
A16: 9 | B16: =H15+Assumptions!$B$7 -> 90.198749 | C16: =B16/Assumptions!$B$6 -> 0.03006625 | D16: =(C16*(Assumptions!$B$10/Assumptions!$B$9))*760/(1+(C16*(Assumptions!$B$10/Assumptions!$B$9))) -> 33.946032 | E16: =1730.63/(8.07131-LOG10(D16))-233.426 -> 31.175246 | F16: =MAX(B16-$H$6,0) -> 66.666053 | G16: =$B$4*F16 -> 49.99954 | H16: =B16-G16 -> 40.199209 | I16: =G16/Assumptions!$B$7 -> 0.9999908
A17: 10 | B17: =H16+Assumptions!$B$7 -> 90.199209 | C17: =B17/Assumptions!$B$6 -> 0.030066403 | D17: =(C17*(Assumptions!$B$10/Assumptions!$B$9))*760/(1+(C17*(Assumptions!$B$10/Assumptions!$B$9))) -> 33.946198 | E17: =1730.63/(8.07131-LOG10(D17))-233.426 -> 31.175331 | F17: =MAX(B17-$H$6,0) -> 66.666513 | G17: =$B$4*F17 -> 49.999885 | H17: =B17-G17 -> 40.199324 | I17: =G17/Assumptions!$B$7 -> 0.9999977
A18: 11 | B18: =H17+Assumptions!$B$7 -> 90.199324 | C18: =B18/Assumptions!$B$6 -> 0.030066441 | D18: =(C18*(Assumptions!$B$10/Assumptions!$B$9))*760/(1+(C18*(Assumptions!$B$10/Assumptions!$B$9))) -> 33.946239 | E18: =1730.63/(8.07131-LOG10(D18))-233.426 -> 31.175353 | F18: =MAX(B18-$H$6,0) -> 66.666628 | G18: =$B$4*F18 -> 49.999971 | H18: =B18-G18 -> 40.199352 | I18: =G18/Assumptions!$B$7 -> 0.99999942
A19: 12 | B19: =H18+Assumptions!$B$7 -> 90.199352 | C19: =B19/Assumptions!$B$6 -> 0.030066451 | D19: =(C19*(Assumptions!$B$10/Assumptions!$B$9))*760/(1+(C19*(Assumptions!$B$10/Assumptions!$B$9))) -> 33.946249 | E19: =1730.63/(8.07131-LOG10(D19))-233.426 -> 31.175358 | F19: =MAX(B19-$H$6,0) -> 66.666657 | G19: =$B$4*F19 -> 49.999993 | H19: =B19-G19 -> 40.19936 | I19: =G19/Assumptions!$B$7 -> 0.99999986
A22: OUTLET TEMPERATURE = 5 C | E22: Psat(T), mmHg = | F22: =IF(5>=0,10^(8.07131-1730.63/(233.426+5)),6.1115*EXP(22.452*5/(272.55+5))*0.750062) -> 6.4975195 | G22: Cap(T), kg/hr = | H22: =(($F$22)/(760-$F$22))*(Assumptions!$B$9/Assumptions!$B$10)*Assumptions!$B$6 -> 16.635785
A23: Hour | B23: Vapour Entering, W(in) (kg) | C23: Humidity Ratio, Y (kg/kg) | D23: p(H2O), actual (mmHg) | E23: Dew Point This Hour (C) | F23: Excess Above Capacity (kg) | G23: Condensed This Hour (kg/hr) | H23: Carryover After (kg) | I23: % of Evap. Condensed
A24: 1 | B24: =Assumptions!$B$7 -> 50 | C24: =B24/Assumptions!$B$6 -> 0.016666667 | D24: =(C24*(Assumptions!$B$10/Assumptions!$B$9))*760/(1+(C24*(Assumptions!$B$10/Assumptions!$B$9))) -> 19.199541 | E24: =1730.63/(8.07131-LOG10(D24))-233.426 -> 21.527612 | F24: =MAX(B24-$H$22,0) -> 33.364215 | G24: =$B$4*F24 -> 25.023161 | H24: =B24-G24 -> 24.976839 | I24: =G24/Assumptions!$B$7 -> 0.50046322
A25: 2 | B25: =H24+Assumptions!$B$7 -> 74.976839 | C25: =B25/Assumptions!$B$6 -> 0.02499228 | D25: =(C25*(Assumptions!$B$10/Assumptions!$B$9))*760/(1+(C25*(Assumptions!$B$10/Assumptions!$B$9))) -> 28.431623 | E25: =1730.63/(8.07131-LOG10(D25))-233.426 -> 28.096904 | F25: =MAX(B25-$H$22,0) -> 58.341054 | G25: =$B$4*F25 -> 43.75579 | H25: =B25-G25 -> 31.221049 | I25: =G25/Assumptions!$B$7 -> 0.87511581
A26: 3 | B26: =H25+Assumptions!$B$7 -> 81.221049 | C26: =B26/Assumptions!$B$6 -> 0.027073683 | D26: =(C26*(Assumptions!$B$10/Assumptions!$B$9))*760/(1+(C26*(Assumptions!$B$10/Assumptions!$B$9))) -> 30.703801 | E26: =1730.63/(8.07131-LOG10(D26))-233.426 -> 29.423183 | F26: =MAX(B26-$H$22,0) -> 64.585263 | G26: =$B$4*F26 -> 48.438948 | H26: =B26-G26 -> 32.782101 | I26: =G26/Assumptions!$B$7 -> 0.96877895
A27: 4 | B27: =H26+Assumptions!$B$7 -> 82.782101 | C27: =B27/Assumptions!$B$6 -> 0.027594034 | D27: =(C27*(Assumptions!$B$10/Assumptions!$B$9))*760/(1+(C27*(Assumptions!$B$10/Assumptions!$B$9))) -> 31.269642 | E27: =1730.63/(8.07131-LOG10(D27))-233.426 -> 29.740175 | F27: =MAX(B27-$H$22,0) -> 66.146316 | G27: =$B$4*F27 -> 49.609737 | H27: =B27-G27 -> 33.172364 | I27: =G27/Assumptions!$B$7 -> 0.99219474
A28: 5 | B28: =H27+Assumptions!$B$7 -> 83.172364 | C28: =B28/Assumptions!$B$6 -> 0.027724121 | D28: =(C28*(Assumptions!$B$10/Assumptions!$B$9))*760/(1+(C28*(Assumptions!$B$10/Assumptions!$B$9))) -> 31.410965 | E28: =1730.63/(8.07131-LOG10(D28))-233.426 -> 29.818568 | F28: =MAX(B28-$H$22,0) -> 66.536579 | G28: =$B$4*F28 -> 49.902434 | H28: =B28-G28 -> 33.26993 | I28: =G28/Assumptions!$B$7 -> 0.99804868
A29: 6 | B29: =H28+Assumptions!$B$7 -> 83.26993 | C29: =B29/Assumptions!$B$6 -> 0.027756643 | D29: =(C29*(Assumptions!$B$10/Assumptions!$B$9))*760/(1+(C29*(Assumptions!$B$10/Assumptions!$B$9))) -> 31.446287 | E29: =1730.63/(8.07131-LOG10(D29))-233.426 -> 29.838114 | F29: =MAX(B29-$H$22,0) -> 66.634145 | G29: =$B$4*F29 -> 49.975609 | H29: =B29-G29 -> 33.294321 | I29: =G29/Assumptions!$B$7 -> 0.99951217
A30: 7 | B30: =H29+Assumptions!$B$7 -> 83.294321 | C30: =B30/Assumptions!$B$6 -> 0.027764774 | D30: =(C30*(Assumptions!$B$10/Assumptions!$B$9))*760/(1+(C30*(Assumptions!$B$10/Assumptions!$B$9))) -> 31.455117 | E30: =1730.63/(8.07131-LOG10(D30))-233.426 -> 29.842997 | F30: =MAX(B30-$H$22,0) -> 66.658536 | G30: =$B$4*F30 -> 49.993902 | H30: =B30-G30 -> 33.300419 | I30: =G30/Assumptions!$B$7 -> 0.99987804
A31: 8 | B31: =H30+Assumptions!$B$7 -> 83.300419 | C31: =B31/Assumptions!$B$6 -> 0.027766806 | D31: =(C31*(Assumptions!$B$10/Assumptions!$B$9))*760/(1+(C31*(Assumptions!$B$10/Assumptions!$B$9))) -> 31.457325 | E31: =1730.63/(8.07131-LOG10(D31))-233.426 -> 29.844218 | F31: =MAX(B31-$H$22,0) -> 66.664634 | G31: =$B$4*F31 -> 49.998476 | H31: =B31-G31 -> 33.301944 | I31: =G31/Assumptions!$B$7 -> 0.99996951
A32: 9 | B32: =H31+Assumptions!$B$7 -> 83.301944 | C32: =B32/Assumptions!$B$6 -> 0.027767315 | D32: =(C32*(Assumptions!$B$10/Assumptions!$B$9))*760/(1+(C32*(Assumptions!$B$10/Assumptions!$B$9))) -> 31.457877 | E32: =1730.63/(8.07131-LOG10(D32))-233.426 -> 29.844523 | F32: =MAX(B32-$H$22,0) -> 66.666159 | G32: =$B$4*F32 -> 49.999619 | H32: =B32-G32 -> 33.302325 | I32: =G32/Assumptions!$B$7 -> 0.99999238
A33: 10 | B33: =H32+Assumptions!$B$7 -> 83.302325 | C33: =B33/Assumptions!$B$6 -> 0.027767442 | D33: =(C33*(Assumptions!$B$10/Assumptions!$B$9))*760/(1+(C33*(Assumptions!$B$10/Assumptions!$B$9))) -> 31.458015 | E33: =1730.63/(8.07131-LOG10(D33))-233.426 -> 29.844599 | F33: =MAX(B33-$H$22,0) -> 66.66654 | G33: =$B$4*F33 -> 49.999905 | H33: =B33-G33 -> 33.30242 | I33: =G33/Assumptions!$B$7 -> 0.99999809
A34: 11 | B34: =H33+Assumptions!$B$7 -> 83.30242 | C34: =B34/Assumptions!$B$6 -> 0.027767473 | D34: =(C34*(Assumptions!$B$10/Assumptions!$B$9))*760/(1+(C34*(Assumptions!$B$10/Assumptions!$B$9))) -> 31.458049 | E34: =1730.63/(8.07131-LOG10(D34))-233.426 -> 29.844618 | F34: =MAX(B34-$H$22,0) -> 66.666635 | G34: =$B$4*F34 -> 49.999976 | H34: =B34-G34 -> 33.302444 | I34: =G34/Assumptions!$B$7 -> 0.99999952
A35: 12 | B35: =H34+Assumptions!$B$7 -> 83.302444 | C35: =B35/Assumptions!$B$6 -> 0.027767481 | D35: =(C35*(Assumptions!$B$10/Assumptions!$B$9))*760/(1+(C35*(Assumptions!$B$10/Assumptions!$B$9))) -> 31.458058 | E35: =1730.63/(8.07131-LOG10(D35))-233.426 -> 29.844623 | F35: =MAX(B35-$H$22,0) -> 66.666659 | G35: =$B$4*F35 -> 49.999994 | H35: =B35-G35 -> 33.30245 | I35: =G35/Assumptions!$B$7 -> 0.99999988
A38: OUTLET TEMPERATURE = 0 C | E38: Psat(T), mmHg = | F38: =IF(0>=0,10^(8.07131-1730.63/(233.426+0)),6.1115*EXP(22.452*0/(272.55+0))*0.750062) -> 4.5422258 | G38: Cap(T), kg/hr = | H38: =(($F$38)/(760-$F$38))*(Assumptions!$B$9/Assumptions!$B$10)*Assumptions!$B$6 -> 11.599491
A39: Hour | B39: Vapour Entering, W(in) (kg) | C39: Humidity Ratio, Y (kg/kg) | D39: p(H2O), actual (mmHg) | E39: Dew Point This Hour (C) | F39: Excess Above Capacity (kg) | G39: Condensed This Hour (kg/hr) | H39: Carryover After (kg) | I39: % of Evap. Condensed
A40: 1 | B40: =Assumptions!$B$7 -> 50 | C40: =B40/Assumptions!$B$6 -> 0.016666667 | D40: =(C40*(Assumptions!$B$10/Assumptions!$B$9))*760/(1+(C40*(Assumptions!$B$10/Assumptions!$B$9))) -> 19.199541 | E40: =1730.63/(8.07131-LOG10(D40))-233.426 -> 21.527612 | F40: =MAX(B40-$H$38,0) -> 38.400509 | G40: =$B$4*F40 -> 28.800382 | H40: =B40-G40 -> 21.199618 | I40: =G40/Assumptions!$B$7 -> 0.57600764
A41: 2 | B41: =H40+Assumptions!$B$7 -> 71.199618 | C41: =B41/Assumptions!$B$6 -> 0.023733206 | D41: =(C41*(Assumptions!$B$10/Assumptions!$B$9))*760/(1+(C41*(Assumptions!$B$10/Assumptions!$B$9))) -> 27.050261 | E41: =1730.63/(8.07131-LOG10(D41))-233.426 -> 27.244867 | F41: =MAX(B41-$H$38,0) -> 59.600127 | G41: =$B$4*F41 -> 44.700095 | H41: =B41-G41 -> 26.499523 | I41: =G41/Assumptions!$B$7 -> 0.89400191
A42: 3 | B42: =H41+Assumptions!$B$7 -> 76.499523 | C42: =B42/Assumptions!$B$6 -> 0.025499841 | D42: =(C42*(Assumptions!$B$10/Assumptions!$B$9))*760/(1+(C42*(Assumptions!$B$10/Assumptions!$B$9))) -> 28.98701 | E42: =1730.63/(8.07131-LOG10(D42))-233.426 -> 28.429363 | F42: =MAX(B42-$H$38,0) -> 64.900032 | G42: =$B$4*F42 -> 48.675024 | H42: =B42-G42 -> 27.824499 | I42: =G42/Assumptions!$B$7 -> 0.97350048
A43: 4 | B43: =H42+Assumptions!$B$7 -> 77.824499 | C43: =B43/Assumptions!$B$6 -> 0.0259415 | D43: =(C43*(Assumptions!$B$10/Assumptions!$B$9))*760/(1+(C43*(Assumptions!$B$10/Assumptions!$B$9))) -> 29.469599 | E43: =1730.63/(8.07131-LOG10(D43))-233.426 -> 28.713781 | F43: =MAX(B43-$H$38,0) -> 66.225008 | G43: =$B$4*F43 -> 49.668756 | H43: =B43-G43 -> 28.155743 | I43: =G43/Assumptions!$B$7 -> 0.99337512
A44: 5 | B44: =H43+Assumptions!$B$7 -> 78.155743 | C44: =B44/Assumptions!$B$6 -> 0.026051914 | D44: =(C44*(Assumptions!$B$10/Assumptions!$B$9))*760/(1+(C44*(Assumptions!$B$10/Assumptions!$B$9))) -> 29.590147 | E44: =1730.63/(8.07131-LOG10(D44))-233.426 -> 28.784196 | F44: =MAX(B44-$H$38,0) -> 66.556252 | G44: =$B$4*F44 -> 49.917189 | H44: =B44-G44 -> 28.238554 | I44: =G44/Assumptions!$B$7 -> 0.99834378
A45: 6 | B45: =H44+Assumptions!$B$7 -> 78.238554 | C45: =B45/Assumptions!$B$6 -> 0.026079518 | D45: =(C45*(Assumptions!$B$10/Assumptions!$B$9))*760/(1+(C45*(Assumptions!$B$10/Assumptions!$B$9))) -> 29.620278 | E45: =1730.63/(8.07131-LOG10(D45))-233.426 -> 28.801757 | F45: =MAX(B45-$H$38,0) -> 66.639063 | G45: =$B$4*F45 -> 49.979297 | H45: =B45-G45 -> 28.259256 | I45: =G45/Assumptions!$B$7 -> 0.99958594
A46: 7 | B46: =H45+Assumptions!$B$7 -> 78.259256 | C46: =B46/Assumptions!$B$6 -> 0.026086419 | D46: =(C46*(Assumptions!$B$10/Assumptions!$B$9))*760/(1+(C46*(Assumptions!$B$10/Assumptions!$B$9))) -> 29.62781 | E46: =1730.63/(8.07131-LOG10(D46))-233.426 -> 28.806144 | F46: =MAX(B46-$H$38,0) -> 66.659766 | G46: =$B$4*F46 -> 49.994824 | H46: =B46-G46 -> 28.264432 | I46: =G46/Assumptions!$B$7 -> 0.99989649
...

Sheet Steady-State Summary
A1: Steady-State Summary — All Outlet Temperatures
A2: Values taken at hour 12 of the 'Hour-by-Hour Balance' sheet, by which point all cases have converged
A4: Outlet T (C) | B4: Sat. Capacity at Outlet T (kg/hr) | C4: Steady-State Dew Point (C) | D4: Steady-State Carryover (kg) | E4: Steady-State Condensed (kg/hr) | F4: % of Evap. Condensed
A5: 10 | B5: ='Hour-by-Hour Balance'!H$6 -> 23.532695 | C5: ='Hour-by-Hour Balance'!E19 -> 31.175358 | D5: ='Hour-by-Hour Balance'!H19 -> 40.19936 | E5: ='Hour-by-Hour Balance'!G19 -> 49.999993 | F5: ='Hour-by-Hour Balance'!I19 -> 0.99999986
A6: 5 | B6: ='Hour-by-Hour Balance'!H$22 -> 16.635785 | C6: ='Hour-by-Hour Balance'!E35 -> 29.844623 | D6: ='Hour-by-Hour Balance'!H35 -> 33.30245 | E6: ='Hour-by-Hour Balance'!G35 -> 49.999994 | F6: ='Hour-by-Hour Balance'!I35 -> 0.99999988
A7: 0 | B7: ='Hour-by-Hour Balance'!H$38 -> 11.599491 | C7: ='Hour-by-Hour Balance'!E51 -> 28.807605 | D7: ='Hour-by-Hour Balance'!H51 -> 28.266156 | E7: ='Hour-by-Hour Balance'!G51 -> 49.999995 | F7: ='Hour-by-Hour Balance'!I51 -> 0.9999999
A8: -5 | B8: ='Hour-by-Hour Balance'!H$54 -> 7.6791569 | C8: ='Hour-by-Hour Balance'!E67 -> 27.957322 | D8: ='Hour-by-Hour Balance'!H67 -> 24.345822 | E8: ='Hour-by-Hour Balance'!G67 -> 49.999996 | F8: ='Hour-by-Hour Balance'!I67 -> 0.99999991
A9: -10 | B9: ='Hour-by-Hour Balance'!H$70 -> 4.9606608 | C9: ='Hour-by-Hour Balance'!E83 -> 27.343383 | D9: ='Hour-by-Hour Balance'!H83 -> 21.627326 | E9: ='Hour-by-Hour Balance'!G83 -> 49.999996 | F9: ='Hour-by-Hour Balance'!I83 -> 0.99999992
A11: At steady state, condensed water (kg/hr) equals fresh evaporation (kg/hr) = 50 kg/hr for every outlet temperature, by mass conservation. The dew point of the gas ENTERING the chiller settles at a value well above the outlet temperature in every case (27-31 C vs 10 to -10 C), confirming condensation is sustained at full strength once the loop has built up its steady-state vapour inventory. Colder outlet temperatures reach a LOWER steady-state carryover (less vapour needs to recirculate to force full condensation) and also a slightly lower steady-state dew point.

Sheet Worked Example (0C)
A1: Worked Example — Outlet Temperature = 0 C, Hour 1 and Hour 2 in Full Detail
A2: Demonstrates Raoult's Law, Dalton's Law, and the hour-by-hour recirculation method with no saturation shortcut
A4: HOUR 1
A5: Step | B5: Result | C5: Working
A6: 1. Vapour entering chiller, W(in) | B6: 50.000 kg | C6: No carryover yet (first hour): W(in) = 0 + 50 = 50 kg
A7: 2. Humidity ratio, Y | B7: 0.016667 kg/kg | C7: Y = W(in) / N2 flow = 50 / 3000
A8: 3. Mole ratio, k | B8: 0.025917 | C8: k = Y x (MW_N2/MW_H2O) = 0.016667 x (28.014/18.015)
A9: 4. Actual p(H2O) [Dalton's Law] | B9: 19.200 mmHg | C9: p(H2O) = k x 760 / (1+k)
A10: 5. Dew point this hour | B10: 21.528 C | C10: Invert Antoine: T = 1730.63/(8.07131-log10(19.200)) - 233.426
A11: 6. Psat at outlet T=0C [Raoult's Law ceiling] | B11: 4.542 mmHg | C11: Pure water condensate, x=1 -> p(H2O),equilibrium = Psat(0C); Antoine: 10^(8.07131-1730.63/233.426)
A12: 7. p(N2) at outlet T | B12: 755.458 mmHg | C12: p(N2) = 760 - 4.542
A13: 8. Saturation capacity, Cap | B13: 11.599 kg | C13: Y_sat = (4.542/755.458)x(18.015/28.014) = 0.003866; Cap = 0.003866 x 3000
A14: 9. Excess above capacity | B14: 38.401 kg | C14: Excess = W(in) - Cap = 50 - 11.599
A15: 10. Condensed this hour (eta=0.75) | B15: 28.801 kg/hr | C15: Condensed = 0.75 x 38.401
A16: 11. Carryover to Hour 2 | B16: 21.199 kg | C16: Carryover = W(in) - Condensed = 50 - 28.801
A18: HOUR 2
A19: Step | B19: Result | C19: Working
A20: 1. Vapour entering chiller, W(in) | B20: 71.199 kg | C20: Carryover from Hour 1 + fresh evap = 21.199 + 50
A21: 2. Humidity ratio, Y | B21: 0.023733 kg/kg | C21: Y = 71.199 / 3000
A22: 3. Mole ratio, k | B22: 0.036911 | C22: k = 0.023733 x (28.014/18.015)
A23: 4. Actual p(H2O) [Dalton's Law] | B23: 27.050 mmHg | C23: p(H2O) = 0.036911 x 760 / 1.036911
A24: 5. Dew point this hour | B24: 27.245 C | C24: T = 1730.63/(8.07131-log10(27.050)) - 233.426 -- HIGHER than Hour 1's 21.528 C
A25: 6. Saturation capacity, Cap (unchanged) | B25: 11.599 kg | C25: Cap depends only on outlet T = 0C, not on the hour
A26: 7. Excess above capacity | B26: 59.600 kg | C26: Excess = 71.199 - 11.599
A27: 8. Condensed this hour (eta=0.75) | B27: 44.700 kg/hr | C27: Condensed = 0.75 x 59.600
A28: 9. Carryover to Hour 3 | B28: 26.499 kg | C28: Carryover = 71.199 - 44.700
A30: KEY OBSERVATION: the dew point ROSE from 21.53 C (Hour 1) to 27.25 C (Hour 2) because more water vapour is now circulating in the loop -- the incoming gas is more humid, so it has a higher dew point. The saturation CAPACITY at the 0C outlet stayed fixed at 11.599 kg because that depends only on the fixed outlet temperature (via Raoult's Law / Antoine equation), never on how much vapour is arriving. This is why the two must be tracked separately and recalculated every hour rather than assumed equal.

Sheet Reverse Engineering
A1: Reverse Engineering — Required Outlet Temperature for Target Steady-State Condensation %
A2: Based on saturation capacity at outlet T (Raoult's Law ceiling) needed to force the target % once the loop reaches steady state
A4: Target Steady-State Condensation % | B4: Required Outlet Temperature (C) | C4: Saturation Capacity Required (kg/hr) | D4: Note
A5: 0.7 | B5: 3.544 | C5: 15 | D5: Liquid water regime
A6: 0.8 | B6: -1.889 | C6: 10 | D6: Ice regime
A7: 0.9 | B7: -9.911 | C7: 5 | D7: Ice regime
A8: 0.95 | B8: -17.485 | C8: 2.5 | D8: Ice regime
A9: 0.99 | B9: -33.511 | C9: 0.5 | D9: Ice regime
A11: At steady state, condensed always equals 50 kg/hr (mass conservation), so 'target condensation %' here refers to how close the SINGLE-PASS removal is to the steady demand -- equivalently, the saturation capacity Cap(T) = Evap_rate x (1-target%). Since Cap(T) is set purely by the outlet temperature through the Raoult's Law ceiling (Psat(T)), the required T is found by inverting that relationship numerically.

Sheet Discussion
A1: Engineering Discussion
A2: Dew point behaviour, ice formation risk, and scale-up recommendation
A4: WHY THE DEW POINT RISES OVER TIME, NOT FALLS
A5: Each hour, fresh evaporation (50 kg/hr) adds to whatever vapour the chiller failed to remove last hour (carryover). Because the incoming gas keeps gaining more total water vapour relative to the fixed N2 flow, its humidity ratio rises hour over hour, and a higher humidity ratio always corresponds to a HIGHER dew point, not a lower one. This continues until the loop reaches steady state, at which point the dew point settles at its highest, equilibrium value -- around 27-31 C across the five outlet temperatures studied here, always comfortably above the chiller outlet temperature, which is why condensation is sustained at its maximum rate once steady state is reached.
A7: ICE FORMATION RISK BELOW 0C
A8: Below 0C, the condensed water freezes onto the chiller's heat-transfer surfaces rather than draining as liquid, forming an insulating frost layer. This progressively reduces heat-transfer area and airflow cross-section, causing the real outlet temperature to drift upward over time, raises pressure drop and blower load, and typically requires a periodic defrost cycle that interrupts continuous operation.
A10: PRACTICAL OPERATING LIMITATIONS
A11: Refrigeration duty rises sharply as outlet T drops, since both sensible and latent heat removal increase while refrigeration cycle COP falls as evaporator temperature decreases. Below 0C typically requires glycol or two-stage cascade refrigeration instead of a simple chilled-water loop. Defrost cycles reduce effective uptime. Real chiller efficiency (eta) likely degrades further as ice builds up, meaning the real system may need an even colder design point than this ideal calculation suggests.
A13: RECOMMENDED OUTLET TEMPERATURE FOR SCALE-UP
A14: An outlet temperature of approximately -5C to 0C is recommended. This range achieves strong single-pass removal while staying close enough to the ice point that standard single-stage mechanical refrigeration remains viable, with manageable defrost requirements. Pushing to -10C buys only a modest further improvement in steady-state carryover for materially higher refrigeration duty and ice-management complexity.
